Workbook

Sheet individual (2)
B2: Formulario solicitud de suministro
B4: DATOS DEL SUMINISTRO
B6: Departamento | G6: Localidad
B8: Calle | G8: Nro. de puerta | L8: Duplicador
B10: Aviso de Acceso | L10: Desea recibir las notificaciones en esta direccion
B13: DATOS DEL CLIENTE
B15: Nombre | G15: Apellido | L15: Cedula / RUT
B17: Telefono de contacto | G17: Email
B21: Dirección de envío de notificaciones
B23: Calle | G23: nro. de puerta | L23: Apartamento
B25: Departamento | G25: Localidad
B28: DATOS TÉCNICOS DE LA SOLICITUD
B30: Tipo de Solicitud Individual | F30: Pasa Linea | J30: Acometida
B32: Trámite | F32: Requerimiento | J32: Actividad
B34: Trámite asociado
B36: Tensión suministro | F36: Tarifa | J36: Fases
B38: Potencia solicitada | F38: Potencia en Punta-Llano | J38: Potencia en Valle
B41: Certificado de carga | F41: Instalada en calefacción
B44: La instalación incluye alguna carga perturbadora o sensible
B48: Observaciones

Sheet Inicio

Sheet Individual
B5: DATOS DEL SUMINISTRO
B7: Departamento * | E7: Localidad * | H7: Padrón / Nro. Medidor vecino
B9: Calle * | E9: Nro. de puerta * | H9: Duplicador | K9: Apartamento
B12: Aviso de Acceso / Esquina * | J12: ¿Desea recibir las notificaciones en esta dirección? *
B15: DATOS DEL CLIENTE
B17: Documento * | E17: Nro * | H17: =IF(B18="Otros","Indicar tipo de documento","")
K18: =IF(B18="Otros","CI extranjera, pasaporte, BPS, etc.","")
B19: =IF(B18="RUT","Razón Social","Nombre y apellido") -> Nombre y apellido | E19: Teléfono de contacto * | H19: Email *
B23: Dirección de envío de notificaciones
B25: Calle | E25: Nro. de puerta | H25: Duplicador | K25: Apartamento
B27: Departamento | E27: Localidad
B30: DATOS TÉCNICOS DE LA SOLICITUD
B32: Tipo de Solicitud Individual * | E32: Pasa Línea * | H32: Acometida *
B34: Trámite * | E34: Requerimiento | F34: * | H34: Actividad *
B36: Trámite asociado | E36: Tipo puesta de medida *
H37: =IF(B35="Provisorio General *","En Observaciones (al final del formulario) debe indicar: fecha inicio/fin del provisorio, asi como horas diarias estimadas de utilización","")
B38: Tensión suministro * | E38: Tarifa * | H38: Fases *
B40: Potencia solicitada *
E41: =IF(B41="Potencia excepcional","Seleccionar","") | G41: =IFERROR(VLOOKUP(F41,check!E43:F48,2,FALSE),"")
E42: =IF(B41="Mayor a 40 KW","Ingresar","")
B44: Doble contratación de Potencia | D44: Si/No
B45: Potencia en Valle | E45: Potencia en Punta - Llano
B46: =IF(E44="Si",IF(B41="Mayor a 40 KW",F42,B41),"")
B48: Certificado de carga * | E48: Instalada en calefacción * | H48: La instalación incluye alguna carga perturbadora o sensible *
B53: Observaciones
B65: * Ejemplo: Coordenadas del servicio.
B67: Al finalizar guardar el archivo y adjuntar en el formulario del portal.
B72: * Campo Obligatorio

Sheet Colectiva
B6: DATOS DEL SUMINISTRO
B8: Departamento * | E8: Localidad * | H8: Padrón / Nro. Medidor vecino
B10: Calle * | E10: Nro. de puerta * | H10: Duplicador
H12: =IF(G12=1,"Presentar document tal","")
B13: Aviso de Acceso / Esquina * | J13: ¿Desea recibir notificaciones en esta dirección?
B16: DATOS DEL CLIENTE
B18: Documento * | E18: Nro * | H18: =IF(B19="Otros","Indicar tipo de documento","")
K19: =IF(B19="Otros","CI extranjera, pasaporte, BPS, etc.","")
B20: =IF(B19="RUT","Razón Social","Nombre y apellido") -> Nombre y apellido | E20: Teléfono de contacto * | H20: Email *
B24: Dirección de envío de notificaciones
B26: Calle | E26: Nro. de puerta | H26: Duplicador | K26: Apartamento
B28: Departamento | E28: Localidad
B31: DATOS TÉCNICOS DE LA SOLICITUD
B33: Tipo de Solicitud Colectiva * | E33: Pasa Línea * | H33: Acometida * | K33: Tensión suministro *
B35: Trámite asociado | E35: Requerimiento | F35: * | H35: Actividad * | K35: Tipo puesta de medida *
B40: Agregar centralización * | K40: Agrega Servicio descentralizado *
B42: Si necesita más servicios de los que puede ingresar en el siguiente cuadro (70), entrar aquí.
B44: Nro | C44: Nro. de apartamento | D44: Fases | E44: Tarifa | F44: Tensión | G44: Destino del suministro | H44: Potencia | K44: Nro | L44: Nro. de apartamento | M44: Fases | N44: Tarifa | O44: Tensión | P44: Destino del suministro | Q44: Potencia
H45: Potencia (Máx) | I45: Potencia Punta - Llano | Q45: Potencia (Máx) | R45: Potencia Punta - Llano
B121: Observaciones
B133: * Ejemplo: Coordenadas del servicio.
B135: Al finalizar guardar el archivo y adjuntar en el formulario del portal.
B139: * Campo Obligatorio

Sheet Colectiva (2)
B6: DATOS TÉCNICOS DE LA SOLICITUD
B9: Agregar centralización * | K9: Agrega Servicio descentralizado *
B11: Nro | C11: Nro. de apartamento | D11: Fases | E11: Tarifa | F11: Tensión | G11: Destino del suministro | H11: Potencia | K11: Nro | L11: Nro. de apartamento | M11: Fases | N11: Tarifa | O11: Tensión | P11: Destino del suministro | Q11: Potencia
H12: Potencia (Máx) | I12: Potencia Punta - Llano | Q12: Potencia (Máx) | R12: Potencia Punta - Llano
B101: Si se necesitan mas suministros insertar fila.
B105: Observaciones
B117: * Ejemplo: Coordenadas del servicio.
B119: Al finalizar guardar el archivo y adjuntar en el formulario del portal.
B123: * Campo Obligatorio

Sheet Reconexion
B5: DATOS DEL SUMINISTRO
B7: Departamento * | E7: Localidad * | H7: Padrón / Nro. Medidor vecino | K7: Cuenta *
B9: Calle * | E9: Nro. de puerta * | H9: Duplicador | K9: Apartamento
B12: Aviso de Acceso / Esquina *
B15: DATOS DEL CLIENTE
B17: La persona ya es titular del suministro actualmente:
B19: Documento | E19: Nro | H19: =IF(B20="Otros","Indicar tipo de documento","")
K20: =IF(B20="Otros","CI extranjera, pasaporte, BPS, etc.","")
B21: =IF(B20="RUT","Razón Social","Nombre y apellido") -> Nombre y apellido | E21: Telefono de contacto | H21: Email
B26: Observaciones
B38: * Ejemplo: Coordenadas del servicio.
B40: Al finalizar guardar el archivo y adjuntar en el formulario del portal.
B45: * Campo Obligatorio

Sheet check
I2: VALIDACIONES PARA FORMATO CLIENTE
M3: Para obligatorios *
B4: Tipo de Solicitud | J4: RUT LARGO | K4: CI 7 LARGO | L4: CI 8 LARGO | M4: OTROS | N4: Caracteres indicados
B5: Colectiva | D5: Documento (ambas) | F5: Tramites: Solicitud individual | I5: Colectiva | J5: =IF(AND(Colectiva!B19="RUT",N5=12),TRUE) -> FALSE | K5: =IF(AND(Colectiva!B19="CI",N5=7),TRUE) -> FALSE | L5: =IF(AND(Colectiva!B19="CI",N5=8),TRUE) -> FALSE | M5: =IF(Colectiva!B19="Otros","*","") | N5: =LEN(Colectiva!E19) -> 0
B6: Solicitud de Servicio Colectivo | D6: CI | F6: Nuevo Servicio | I6: Individual | J6: =IF(AND(Individual!B18="RUT",N6=12),TRUE) -> FALSE | K6: =IF(AND(Individual!B18="CI",N6=7),TRUE) -> FALSE | L6: =IF(AND(Individual!B18="CI",N6=8),TRUE) -> TRUE | M6: =IF(Individual!B18="Otros","*","") | N6: =LEN(Individual!E18) -> 8
B7: Solicitud de Consulta Colectiva | D7: RUT | F7: Aumento | I7: Reco | J7: =IF(AND(Reconexion!B20="RUT",N7=12),TRUE) -> FALSE | K7: =IF(AND(Reconexion!B20="CI",N7=7),TRUE) -> FALSE | L7: =IF(AND(Reconexion!B20="CI",N7=8),TRUE) -> FALSE | M7: =IF(Reconexion!B20="Otros","*","") | N7: =LEN(Reconexion!E20) -> 0
B8: Fraccionamiento | D8: Otros | F8: Reducción
F9: Rehabilitación
B10: Individual | F10: Solicitud Instalación de Enlace
B11: Definitiva | D11: Tarifa (ambas) | F11: Provisorio General *
B12: Estimativa | D12: Residencial Simple | F12: Provisorio Obra
D13: Residencial Doble
D14: Residencial Triple
B15: Pasa Línea (ambras) | D15: General Simple
B16: Si | D16: General Hora Estacional
B17: No | D17: Zafra Estival | F17: Destino suministro (ambas)
B18: No Declara | D18: Medianos Consumidores | F18: Residencial
D19: Grandes Consumidores | F19: General
B21: Acometida (ambas)
B22: Aérea | D22: Niveles de tensión (ambas) | F22: Potencia Monofasico | G22: Potencia excepcional | H22: Potencia trifasico | I22: Mono + excep
B23: Subterránea | D23: 230 V | F23: 3.5 | G23: 1.5 | H23: 6 | I23: 3.5
D24: 400 V | F24: 4 | G24: 2 | H24: 8 | I24: 4
D25: 6,4 KV | F25: 4.5 | G25: 2.5 | H25: 10 | I25: 4.5
B26: Requerimiento (ambas) | D26: 15 KV | F26: 5 | G26: 3 | H26: 12 | I26: 5
B27: Informe Técnico | D27: 22 KV | F27: 5.5 | G27: 14.5 | H27: 15 | I27: 5.5
B28: Presupuesto | D28: 31,5 KV | F28: 6 | G28: 25 | H28: 20 | I28: 6
B29: Informe Técnico y Presupuesto | D29: 63 KV | F29: 6.5 | H29: 25 | I29: 6.5
F30: 7 | H30: 30 | I30: 7
D31: Fases (ambas) | F31: 7.5 | H31: 35 | I31: 7.5
B32: Tipo de Medida (ambas) | D32: Monofásica | F32: 8 | H32: 40 | I32: 8
B33: Centralizado | D33: Trifásica | F33: 8.5 | H33: Mayor a 40 KW | I33: 8.5
B34: Descentralizado | F34: 9 | I34: 9
F35: 9.5 | I35: 9.5
F36: 10 | I36: 10
B37: Departamento | F37: 10.5 | I37: 10.5
B38: Artigas | F38: 11 | I38: 11
B39: Canelones | F39: 11.5 | I39: 11.5
B40: Cerro Largo | F40: Potencia excepcional | I40: 1.5
B41: Colonia | I41: 2
B42: Durazno | E42: Letra chica | I42: 2.5
...
