Workbook

Sheet Costeo China
B1: DATOS | E1: COSTEO | J1: PRICING
B2: Potencia (kW) | C2: 5 | E2: Item | F2: Costo unitario (USD sin iva) | G2: Cantidad | H2: Costo subtotal (USD sin iva) | J2: Item | K2: Valor (USD sin iva)
B3: Dólar | C3: 45 | E3: Paneles 300 W | F3: 150 | G3: =MROUND(1.15*C2*1000/300,1) -> 19 | H3: =+F3*G3 -> 2850 | I3: =+H3/C2/1000 -> 0.57 | J3: Costos | K3: =+H11 -> 5280
B4: Margen negocio (%) | C4: 0.15 | E4: Cables FV (m) | F4: 1.5 | G4: =+$C$2*40*1000/5000 -> 40 | H4: =+F4*G4 -> 60 | J4: Mano de obra | K4: =+(F13*H13+F14*H14+F15*H15)/C3 -> 1013.3333
B5: TIR inversionista (%) | C5: 0.4 | E5: Cables BVR (m) | F5: 1.5 | G5: =+$C$2*40*1000/5000 -> 40 | H5: =+F5*G5 -> 60 | J5: Margen | K5: =+(K3+K4)*C4 -> 944
B6: Inversion VOLTIA (USD) | C6: 0 | E6: Conectores | F6: 10 | G6: =+G7*2 -> 4 | H6: =+F6*G6 -> 40
B7: Plazo (días) | C7: 60 | E7: Protección | F7: 130 | G7: =+C2*2*1000/5000 -> 2 | H7: =+F7*G7 -> 260 | J7: Subtotal | K7: =+SUM(K3:K5) -> 7237.3333
E8: Inversor | F8: 1250 | G8: =ROUNDUP(C2*1000/6000,0) -> 1 | H8: =+F8*G8 -> 1250 | J8: IVA | K8: =+K7*0.22 -> 1592.2133
B9: INVERSIÓN | E9: Estructura | F9: 40 | G9: =+G3 -> 19 | H9: =+F9*G9 -> 760
A11: Inversionista | B11: Inversión (USD) | C11: =+H11-C6 -> 5280 | G11: TOTAL | H11: =+SUM(H3:H9) -> 5280 | J11: TOTAL | K11: =+K7+K8 -> 8829.5467
B12: Porcentaje inversionista | C12: =+C11/H11 -> 1
B13: Ganancia de inversionista (USD) | C13: =C11*C5*C7/365 -> 347.17808 | E13: Hora técnico CAT A ($) | F13: 1800 | G13: Horas CAT A | H13: =4*G8 -> 4 | J13: Ahorro mes ($) | K13: 5000
B14: Rentabilidad de inversión | C14: =C13/C11 -> 0.065753425 | E14: Hora técnico CAT C ($) | F14: 1000 | G14: Horas CAT C | H14: 24 | J14: Ahorro mes (USD) | K14: =+K13/C3 -> 111.11111
B15: TIR | C15: =(365/C7)*C14 -> 0.4 | E15: Hora técnico CAT D ($) | F15: 600 | G15: Horas CAT D | H15: 24
E16: Costo técnico CAT A ($) | F16: =+H13*F13 -> 7200 | G16: =+F16/$C$3 -> 160 | J16: Tiempo de recuperación (meses) | K16: =+K11/K14 -> 79.46592
A17: VOLTIA | B17: Porcentaje inversión VOLTIA | C17: =+C6/H11 -> 0 | E17: Costo técnico CAT C ($) | F17: =+H14*F14 -> 24000 | G17: =+F17/$C$3 -> 533.33333
B18: Ganancia VOLTIA (USD) | C18: =K5-C13 -> 596.82192 | E18: Costo técnico CAT D ($) | F18: =+H15*F15 -> 14400 | G18: =+F18/$C$3 -> 320 | J18: Tiempo de recuperación (años) | K18: =+K16/12 -> 6.62216
B19: Rentabilidad inversión VOLTIA | C19: =IF(C6>0,C18/C6,"inf") -> inf
B20: TIR | C20: =(365/C7)*C19 -> #VALUE!
J21: Ganancia anual | K21: =+K14*12 -> 1333.3333
J22: Rentabilidad anual | K22: =+K21/K11 -> 0.15100813

Sheet Calculadora China
A2: Cajas | B2: 1 | C2: 2 | D2: 10 | E2: 14 | F2: 15 | G2: 20 | H2: 28 | I2: 30 | J2: 60 | K2: 100
A3: Metros cuadrados | B3: =+ROUNDUP(B2/$B$20,0) -> 1 | C3: =+ROUNDUP(C2/$B$20,0) -> 1 | D3: =+ROUNDUP(D2/$B$20,0) -> 1 | E3: =+ROUNDUP(E2/$B$20,0) -> 1 | F3: =+ROUNDUP(F2/$B$20,0) -> 2 | G3: =+ROUNDUP(G2/$B$20,0) -> 2 | H3: =+ROUNDUP(H2/$B$20,0) -> 2 | I3: =+ROUNDUP(I2/$B$20,0) -> 3 | ... K3: =+ROUNDUP(K2/$B$20,0) -> 8
A4: Potencia | B4: 600 | C4: 600 | D4: =+$B$4*D2 -> 6000 | E4: =+$B$4*E2 -> 8400 | F4: =+$B$4*F2 -> 9000 | G4: =+$B$4*G2 -> 12000 | H4: =+$B$4*H2 -> 16800 | I4: =+$B$4*I2 -> 18000 | J4: =+$B$4*J2 -> 36000 | K4: =+$B$4*K2 -> 60000
A5: Producto | B5: 157.14 | C5: =+$B$5*C2 -> 314.28 | D5: =+$B$5*D2 -> 1571.4 | E5: =+$B$5*E2 -> 2199.96 | F5: =+$B$5*F2 -> 2357.1 | G5: =+$B$5*G2 -> 3142.8 | H5: =+$B$5*H2 -> 4399.92 | I5: =+$B$5*I2 -> 4714.2 | J5: =+$B$5*J2 -> 9428.4 | K5: =+$B$5*K2 -> 15714
A6: Comision | B6: 27.71 | C6: 46.88 | D6: 200.25 | E6: 276.94 | F6: 304.65 | G6: 400.5 | H6: 553.87 | I6: 600.75 | J6: 1192.96 | K6: 1985.43
A7: Gastos origen | B7: 70 | C7: 70 | D7: 70 | E7: 70 | F7: 140 | G7: 140 | H7: 140 | I7: 210 | J7: 350 | K7: =+K3*$B$21 -> 560
A8: Gastos destino e impuestos | B8: 410.28 | C8: 504.57 | D8: 1258.84 | E8: 1635.98 | F8: 1998.26 | G8: 2469.68 | H8: 3223.95 | I8: 3680.52 | J8: 7045.04 | K8: =+$B$23*K3+K5*$B$24 -> 11956.4
A9: Fletes y seguro | B9: 395 | C9: 395 | D9: 395 | E9: 395 | F9: 730 | G9: 730 | H9: 730 | I9: 1065 | J9: 1735 | K9: =+LOOKUP(K3,D20:D29,E20:E29)*K3 -> 2600
A11: TOTAL | B11: =SUM(B5:B10) -> 1060.13 | C11: =SUM(C5:C10) -> 1330.73 | D11: =SUM(D5:D10) -> 3495.49 | E11: =SUM(E5:E10) -> 4577.88 | F11: =SUM(F5:F10) -> 5530.01 | G11: =SUM(G5:G10) -> 6882.98 | H11: =SUM(H5:H10) -> 9047.74 | I11: =SUM(I5:I10) -> 10270.47 | ... K11: =SUM(K5:K10) -> 32815.83
A14: $/W origen | B14: =+B5/B4 -> 0.2619 | C14: =+C5/C4 -> 0.5238 | D14: =+D5/D4 -> 0.2619 | E14: =+E5/E4 -> 0.2619 | F14: =+F5/F4 -> 0.2619 | G14: =+G5/G4 -> 0.2619 | H14: =+H5/H4 -> 0.2619 | I14: =+I5/I4 -> 0.2619 | J14: =+J5/J4 -> 0.2619
A15: $/W final | B15: =+B11/B4 -> 1.7668833 | C15: =+C11/C4 -> 2.2178833 | D15: =+D11/D4 -> 0.58258167 | E15: =+E11/E4 -> 0.54498571 | F15: =+F11/F4 -> 0.61444556 | G15: =+G11/G4 -> 0.57358167 | H15: =+H11/H4 -> 0.53855595 | I15: =+I11/I4 -> 0.57058167 | ... K15: =+K11/K4 -> 0.5469305
A19: Potencia/caja | B19: 600 | D19: Metros | E19: Flete/metro | G19: Calculadora
A20: Cajas por metro | B20: 14 | D20: 1 | E20: 395 | G20: Cajas | I20: 10
A21: Gastos origen/metro | B21: 70 | D21: 2 | E21: 365 | G21: Potencia (kW) | I21: =+I20*B19/1000 -> 6
A22: Comision | B22: 0.1274 | D22: 3 | E22: 355 | G22: Metros | I22: =+ROUNDUP(I20/$B$20,0) -> 1
A23: Gastos destino/metro | B23: 316 | D23: 4 | E23: 350 | G23: Producto (USD) | I23: =+I20*B26 -> 1571.4
A24: Impuesto | B24: 0.6 | D24: 5 | E24: 347 | G24: Comision (USD) | I24: =+I23*B22 -> 200.19636
A25: Flete/metro | B25: 395 | D25: 6 | E25: 345 | G25: Gastos origen (USD) | I25: =+I22*B21 -> 70
A26: Precio por caja | B26: 157.14 | D26: 7 | E26: 326.4 | G26: Gastos destino e impuestos (USD) | I26: =+B23*I22+I23*B24 -> 1258.84
D27: 8 | E27: 325 | G27: Fletes y seguro (USD) | I27: =+LOOKUP(I22,D20:D29,E20:E29)*I22 -> 395
D28: 9 | E28: 324
D29: 10 | E29: 323 | G29: TOTAL (USD sin iva) | I29: =SUM(I23:I28) -> 3495.4364
A30: Costo cada panel | G30: USD/W final (sin iva) | I30: =+I29/I21/1000 -> 0.58257273

Sheet Costeo URU (monotributo)
B1: DATOS | E1: COSTEO | I1: PRICING | L1: Flujo de caja (USD)
B2: Potencia (kW) | C2: 5 | E2: Item | F2: Costo subtotal (USD sin iva) | G2: Costo subtotal (USD con iva) | I2: Item | J2: Valor (USD) | L2: Cobro adelanto cliente | M2: =+C7 -> 7193.7117
B3: Dólar | C3: 40 | E3: Equipamiento | F3: =+Costos!E10 -> 4810 | G3: =+F3*1.22 -> 5868.2 | I3: Costos | J3: =+G11 -> 10009.939 | L3: Cobro inversionista | M3: =+C14 -> 0
B4: Margen negocio (%) | C4: 0.25 | E4: Costos fijos | F4: =+Costos!I21/2 -> 3760.421 | G4: =+Costos!J21/2 -> 3797.0887 | I4: Mano de obra | J4: =0.3*C2*1000 -> 1500 | L4: Subtotal | M4: =SUM(M2:M3) -> 7193.7117
B5: TIR inversionista (%) | C5: 0.2 | E5: Costos variables | F5: =+Costos!M11 -> 282.5 | G5: =+F5*1.22 -> 344.65 | I5: Margen | J5: =+(J3+J4)*C4 -> 2877.4847 | L5: Pago al provedor | M5: =-G11 -> -10009.939
B6: Inversion VOLTIA (USD) | C6: =+G11-C7 -> 2816.227 | I6: Ventas | J6: =IF(C10="Si",SUM(J3:J5)/19,0) -> 0 | K6: =+J6*C3 -> 0 | L6: Subtotal | M6: =SUM(M4:M5) -> -2816.227
B7: Pago inicial cliente (USD) | C7: =+J12/2 -> 7193.7117 | I7: Subtotal | J7: =+SUM(J3:J6) -> 14387.423 | L7: Cobro saldo cliente | M7: =+J12-C7 -> 7193.7117
B8: Plazo (días) | C8: 90 | L8: Pago mano de obra | M8: =-J4 -> -1500
B9: Equipamiento | C9: Minimo
B10: Vendedor | C10: No | L10: Subtotal | M10: =SUM(M6:M8) -> 2877.4847 | R10: Hotel | S10: 2200 | T10: =+S10*4 -> 8800
E11: TOTAL (sin iva) | F11: =+SUM(F3:F10) -> 8852.921 | G11: =+SUM(G3:G10) -> 10009.939 | I11: TOTAL (USD sin iva) | J11: =+J7 -> 14387.423 | K11: =+J11/20 -> 719.37117 | L11: Pago inversionista | M11: =-C14-C16 -> 0 | R11: Comida | S11: 2000 | T11: =+S11*4 -> 8000
B12: INVERSIÓN | I12: TOTAL (USD iva inc) | J12: =+J11 -> 14387.423 | L12: Subtotal | M12: =SUM(M10:M11) -> 2877.4847 | R12: Nafta | T12: 1500
L13: Pago IVA | M13: =-J8 -> 0 | R13: Flete | T13: 10000
A14: Inversionista | B14: Inversión (USD) | C14: =G11-C7-C6 -> 0 | E14: Hora técnico CAT A ($) | F14: 800 | I14: Ahorro mes ($) | J14: 2200 | L14: Devolución IVA | T14: =SUM(T10:T13) -> 28300
B15: Porcentaje inversionista | C15: =+C14/G11 -> 0 | E15: Hora técnico CAT C ($) | F15: 500 | I15: Ahorro mes (USD) | J15: =+J14/$C$3 -> 55 | L15: Pago IRAE | M15: =-J10 -> 0
B16: Ganancia de inversionista (USD) | C16: =C14*C5*C8/365 -> 0 | E16: Hora técnico CAT D ($) | F16: 350 | L16: Ganancia final | M16: =SUM(M12:M15) -> 2877.4847
B17: Rentabilidad de inversión | C17: =C16/C14 -> #DIV/0! | E17: Costo técnico CAT A ($) | F17: =+F20*F14 -> 24000 | I17: PRI (meses) | J17: =+J12/J15 -> 261.58952
B18: TIR | C18: =(365/C8)*C17 -> #DIV/0! | E18: Costo técnico CAT C ($) | F18: =+F21*F15 -> 40000 | I18: PRI (años) | J18: =+J17/12 -> 21.799126
E19: Costo técnico CAT D ($) | F19: =+F22*F16 -> 28000 | I19: Ganancia anual | J19: =+J15*12 -> 660
A20: VOLTIA | B20: Porcentaje inversión VOLTIA | C20: =+C6/G11 -> 0.28134308 | E20: Horas CAT A | F20: =6*C2 -> 30 | G20: 150000 | I20: TIR | J20: =+J19/J12 -> 0.045873398
B21: Ganancia VOLTIA (USD) | C21: =J5-C16-J10 -> 2877.4847 | E21: Horas CAT C | F21: =+F22 -> 80 | G21: 70000
B22: Rentabilidad inversión VOLTIA | C22: =IF(C6>0,C21/C6,"inf") -> 1.0217517 | E22: Horas CAT D | F22: =+C2*C26*2 -> 80 | G22: 50000 | I22: USD/W | J22: =+J12/C2/1000 -> 2.8774847
B23: TIR | C23: =(365/C8)*C22 -> 4.1437707 | E23: =+F17/$C$3 -> 600
E24: =+F18/$C$3 -> 1000
E25: =+F19/$C$3 -> 700
B26: Horas/kW | C26: 8

Sheet CALCULADORA
B1: DATOS | E1: COSTEO | I1: PRICING | L1: Flujo de caja (USD) | O1: Cuanto paga de UTE? | P1: Cantidad de Paneles estimado
A2: Datos cliente | B2: Nombre cliente | C2: José González | E2: Item | F2: Costo subtotal (USD sin iva) | G2: Costo subtotal (USD con iva) | I2: Item | J2: Valor (USD sin iva) | L2: Cobro adelanto cliente | M2: =+F24 -> 6423.0711 | Q2: Multiplexacion | R2: 4 | V2: Hora técnico Elec ($) | W2: 814
B3: Dirigido a | C3: Estimado José | E3: Equipamiento | F3: =+Costos!E10 -> 4810 | G3: =+F3*1.22 -> 5868.2 | I3: Costos | J3: =+F12 -> 6972.7105 | L3: Pago al provedor | M3: =-G12 -> -8111.3943 | O3: 4000 | P3: 8 | Q3: Ganancia mes | R3: =+R2*M12 -> 6499.7684 | S3: 12 | T3: 2 | U3: {=+_xlfn.IFS(C14<=S3,T3,C14<=S4,T4,C14<=S5,T5,C14<=S6,T6,C14<=S7,T7,C14<=S8,T8,C14>S8,8)} -> 2 | V3: Hora técnico Capataz ($) | W3: 947 | AG3: Verifica Techo | AH3: Verifica Potencia | AI3: Verifica UTE | AJ3: Si
B4: Ciudad | C4: Montevideo, Uruguay. | E4: Costos fijos | F4: =+Costos!I21/R2 -> 1880.2105 | G4: =+Costos!J21/R2 -> 1898.5443 | I4: Mano de obra | J4: =+(W2+W3+W4)*10*U3/C12 -> 1152 | L4: Subtotal | M4: =+M2+M3 -> -1688.3232 | O4: 5000 | P4: 10 | S4: 18 | T4: 3 | V4: Hora técnico CAT D ($) | W4: 543 | AG4: No verifica Techo | AH4: Requiere aumento de Potencia | AI4: No verifica UTE | AJ4: No
A5: Datos Factura UTE | B5: Paga por mes de UTE ($) | C5: 6000 | E5: Costos variables | F5: =+Costos!M11 -> 282.5 | G5: =+F5*1.22 -> 344.65 | I5: Markup | J5: =+(J3+J4)*C13 -> 1624.9421 | L5: Cobro saldo cliente | M5: =+J13-F24 -> 6423.0711 | O5: 6000 | P5: 10 | S5: 30 | T5: 4 | V5: Costo técnico CAT A ($) | W5: =+W10*W2 -> 0
B6: Tarifa | C6: Simple | I6: Comision Ventas | J6: =+(J3+J4+J5)/25 -> 389.98611 | L6: Pago mano de obra | M6: =-J4 -> -1152 | O6: 7000 | P6: 12 | S6: 50 | T6: 5 | V6: Costo técnico CAT C ($) | W6: =+W11*W3 -> 17046
B7: Suministro | C7: trifásico | I7: Comision BBVA | J7: =+J6 -> 389.98611 | L7: Subtotal | M7: =+SUM(M4:M6) -> 3582.748 | O7: 8000 | P7: 12 | S7: 75 | T7: 6 | V7: Costo técnico CAT D ($) | W7: =+W12*W4 -> 9774
B8: Potencia contratada (kW) | C8: 7 | L8: Pago IVA | M8: =-J13+J12 -> -2316.5175 | O8: 9000 | P8: 14 | S8: 100 | T8: 7
A9: Datos techo | B9: Techo | C9: de hormigón de 8 x 4 mts. | I9: Subtotal | J9: =+SUM(J3:J7) -> 10529.625 | L9: Devolución IVA | M9: =+G12-F12 -> 1138.6838
B10: Tamaño techo (m2) | C10: 50 | I10: IVA | J10: =+J9*0.22 -> 2316.5175 | L10: Pago Vendedor | M10: =-J6 -> -389.98611 | O10: 10000 | P10: 14 | V10: Horas CAT A
A11: Datos generales cotización | B11: Distancia instalación (km) | C11: 35 | L11: Pago BBVA | M11: =-J7 -> -389.98611 | O11: 11000 | P11: 16 | V11: Horas CAT C | W11: 18 | X11: 2
B12: Cotización Dólar | C12: 40 | E12: TOTAL (sin iva) | F12: =+SUM(F3:F11) -> 6972.7105 | G12: =+SUM(G3:G11) -> 8111.3943 | I12: TOTAL (USD sin iva) | J12: =+J9 -> 10529.625 | L12: Ganancia final | M12: =+SUM(M7:M11) -> 1624.9421 | O12: 12000 | P12: 16 | V12: Horas CAT D | W12: 18 | X12: 0.75
B13: Markup (%) | C13: 0.2 | I13: TOTAL (USD iva inc) | J13: =+J12*1.22 -> 12846.142
B14: Paneles | C14: 11 | E14: Potencia tot paneles (kW) | F14: =+C14*C15/1000 -> 6.49 | L14: Margen | M14: =+M12/J12 -> 0.15432099
A15: Datos equipos | B15: Potencia cada paneles (W) | C15: 590 | E15: Potencia inversor2 | F15: =+C17*1000 -> 6000
B16: Marca Paneles | C16: RESUN | E16: 24 cuotas | F16: =+'Financiacion BBVA'!C11 -> 22450.239 | I16: Ahorro mes ($) | J16: =+IF(C6="Simple",F14*1000*1.05,F14*1000*0.88) -> 6814.5 | L16: =+IF(C10>=F23,AG3,AG4) -> Verifica Techo | Q16: 4 | R16: 3258 | V16: Sueldo Capataz | W16: 56500 | X16: =+W16*0.8 -> 45200 | Y16: 10000 | Z16: =+W16*1.085 -> 61302.5 | AA16: =+Z16+Y16 -> 71302.5
B17: Potencia inversor (kW) | C17: 6 | E17: 36 cuotas | F17: =+'Financiacion BBVA'!E11 -> 15452.767 | I17: Ahorro mes (USD) | J17: =+J16/$C$12 -> 170.3625 | L17: =+IF(C8>=F19,AH3,AH4) -> Verifica Potencia | Q17: 5 | R17: 6090 | V17: Sueldo Peon | W17: 40000 | X17: =+W17*0.8 -> 32000 | Y17: 0 | Z17: =+W17*1.085 -> 43400 | AA17: =+Z17+Y17 -> 43400
B18: Marca inversor | C18: Growatt | E18: 60 cuotas | F18: =+'Financiacion BBVA'!G11 -> 10543.448 | L18: =+IF(C5>=F25,AI3,AI4) -> Verifica UTE | Q18: 6 | R18: 8501 | V18: Sueldo Electricista | W18: 60000 | X18: =+W18*0.8 -> 48000 | Y18: 10000 | Z18: =+W18*1.085 -> 65100 | AA18: =+Z18+Y18 -> 75100
B19: Fecha | C19: =+TODAY() -> 46205 | E19: Potencia IMG 1 | F19: =+MIN(C17,F14) -> 6 | I19: PRI (meses) | J19: =+J13/J17 -> 75.404753 | K19: =+J12/J17 -> 61.807175 | Q19: 7 | R19: 11304 | AA19: =SUM(AA16:AA18) -> 189802.5 | AB19: =+AA19/4 -> 47450.625
B20: Mes y año | C20: Julio 2026 | E20: Potencia IMG 2 | F20: =+F19*1000 -> 6000 | I20: PRI (años) | J20: =+J19/12 -> 6.2837294 | K20: =+K19/12 -> 5.1505979 | Q20: 8 | R20: 13564 | AB20: =+AB19/40 -> 1186.2656
E21: Paga nuevo ($) | F21: =+C5-J16 -> -814.5 | I21: Ganancia anual | J21: =+J17*12 -> 2044.35 | Q21: 9 | R21: 16537
E22: PRI2 | F22: =+ROUND(J20,0) -> 6 | Q22: 10 | R22: 19239
E23: Metros cuadrados | F23: =+C14*3 -> 33 | I23: TIR | J23: =+J21/J13 -> 0.15914116
E24: Pago inicial cliente (USD) | F24: =+J13/2 -> 6423.0711 | I24: USD/W | J24: =+J13/F14/1000 -> 1.9793748
E25: Energía generada mes (kWh) | F25: =+F14*900 -> 5841
E26: Energia | F26: =+F14*1479 -> 9598.71
E27: Porcentaje ahorro | F27: =+J16/C5 -> 1.13575
B35: Cliente | C35: =+C2 -> José González
B36: Fecha_tapa | C36: =+C20 -> Julio 2026
B37: Fecha | C37: =+TEXT(C19,"d ""de"" mmmm ""de""") & " 2026" -> 2 de julio de 2026
B38: Dirigido | C38: =+C3 -> Estimado José
B39: Lugar | C39: =+C4 -> Montevideo, Uruguay.
B40: Paneles | C40: =+C14 -> 11
B41: Pot_paneles | C41: =+C15 -> 590
B42: Techo | C42: =+C9 -> de hormigón de 8 x 4 mts.
B43: Tamaño | C43: =+F23 -> 33
B44: Pot_IMG | C44: =TEXT(F19, "#.##0") -> 6
B45: Energia | C45: =TEXT(F26, "#.##0")& " kWh" -> 9.599 kWh
B46: Marca_panel | C46: =+C16 -> RESUN
B47: Marca_inversor= Growatt | C47: =+C18 -> Growatt
...

Sheet Costos
A1: COSTEO Equipamiento | H1: COSTOS Fijos mensual | L1: COSTOS Variables
A2: Item | B2: Costo/unidad (USD sin iva) | C2: Costo/unidad (USD con iva) | D2: Cantidad | E2: Costo subtotal (USD sin iva) | F2: Costo subtotal (USD con iva) | H2: Item | I2: Costo subtotal ($ sin iva) | J2: Costo subtotal ($ con iva) | L2: Item | M2: Costo subtotal ($ sin iva) | N2: Costo subtotal ($ con iva)
A3: Paneles | B3: 100 | C3: =+B3*1.22 -> 122 | D3: =+CALCULADORA!C14 -> 11 | E3: =+B3*D3 -> 1100 | F3: =+E3*1.22 -> 1342 | H3: Adelanto IRAE | I3: 6500 | J3: =+I3 -> 6500 | L3: Fletes | M3: =+M5*3 -> 2100 | N3: =+M3*1.22 -> 2562
A4: Estructuras | B4: 90 | C4: =+B4*1.22 -> 109.8 | D4: =+D3 -> 11 | E4: =+B4*D4 -> 990 | F4: =+E4*1.22 -> 1207.8 | H4: BPS | I4: 80000 | J4: =+I4 -> 80000 | L4: Otros | M4: 2000 | N4: =+M4*1.22 -> 2440
A5: Electrica | B5: =+IF(CALCULADORA!C7="monofásico",492,750) -> 750 | C5: =+B5*1.22 -> 915 | D5: 1 | E5: =+D5*B5 -> 750 | F5: =+E5*1.22 -> 915 | H5: Dominio | I5: =659.8/12 -> 54.983333 | J5: =+I5*1.22 -> 67.079667 | L5: Nafta | M5: =+CALCULADORA!C11*2*10 -> 700 | N5: =+M5*1.22 -> 854
A6: Inversor | B6: =+IF(CALCULADORA!C7="monofásico", IF(CALCULADORA!C17<7,1000, 1300), IF(CALCULADORA!C7="trifásico", IF(CALCULADORA!C17<11,1750, IF(CALCULADORA!C14<13,2000, IF(CALCULADORA!C17<21,2200, IF(CALCULADORA!C17<31,2800, IF(CALCULADORA!C17<51,5000, 8000))))))) -> 1750 | C6: =+B6*1.22 -> 2135 | D6: 1 | E6: =+B6*D6 -> 1750 | F6: =+E6*1.22 -> 2135 | H6: Softwares | I6: 2300 | J6: =+I6*1.22 -> 2806 | L6: Alojamiento | M6: 3500 | N6: =+M6*1.22 -> 4270
A7: Meter | B7: =+IF(CALCULADORA!C7="monofásico",110,220) -> 220 | C7: =+B7*1.22 -> 268.4 | D7: 1 | E7: =+B7*D7 -> 220 | F7: =+E7*1.22 -> 268.4 | H7: Local | I7: 32000 | J7: 32000 | L7: Viaticos | M7: 3000 | N7: =+M7*1.22 -> 3660
H8: Contadora | I8: 3278.7 | J8: =+I8*1.22 -> 4000.014
H9: Garantia Local | I9: 2000 | J9: 2000
D10: TOTAL (USD) | E10: =+SUM(E3:E9) -> 4810 | F10: =SUM(F3:F9) -> 5868.2 | H10: Gastos fijos local | I10: 4200 | J10: =+I10*1.22 -> 5124 | L10: TOTAL ($) | M10: =SUM(M3:M9) -> 11300 | N10: =SUM(N3:N8) -> 13786
B11: 1053 | H11: Camion cuota | I11: =350*40 -> 14000 | J11: 14000 | L11: TOTAL (USD) | M11: =+M10/CALCULADORA!$C$12 -> 282.5 | N11: =+N10/CALCULADORA!$C$12 -> 344.65
H12: Sueldos Ventas | I12: 25000 | J12: 25000
D13: IVA (USD) | E13: =+F10-E10 -> 1058.2 | H13: Sueldo CEO | I13: 120000 | J13: 120000 | L13: IVA (USD) | M13: =+N11-M11 -> 62.15
H14: Gastos camion | I14: =5000+3000 -> 8000 | J14: 8000
A15: IVA TOTAL (USD) | B15: =+E13+I23+M13 -> 1193.6853 | H15: Conectividad móvil | I15: 3500 | J15: =+I15*1.22 -> 4270
H20: TOTAL ($) | I20: =SUM(I3:I19) -> 300833.68 | J20: =SUM(J3:J19) -> 303767.09
H21: TOTAL (USD) | I21: =+I20/CALCULADORA!$C$12 -> 7520.8421 | J21: =+J20/CALCULADORA!$C$12 -> 7594.1773
H23: IVA (USD) | I23: =+J21-I21 -> 73.335258

Sheet Detalle costos
A1: Item | B1: Unidades | C1: sin desc | D1: Precio unitario (USD) sin iva | E1: Precio unitario (USD) iva inc | F1: Nota | J1: Paneles | N1: Rieles | R1: Inversores | V1: Presupuestos Energe
A2: MATERIALES ELECTRICOS | J2: Potencia | K2: Precio (iva inc) | L2: Precio/unidad | N2: Item | O2: Precio (iva inc) | P2: Precio/unidad | R2: Marca | S2: Potencia | T2: Precio (iva inc) | V2: Cliente | W2: Potencia | X2: Precio (iva inc) | Y2: USD/W | Z2: Electrica | AA2: Horas | AB2: Instalacion
A3: Interruptor Termomagnético Monofásico | B3: un | C3: 3.6 | D3: =+C3*0.85 -> 3.06 | E3: =+D3*1.22 -> 3.7332 | F3: MGI | J3: 550 | K3: 400 | L3: =+K3/J3 -> 0.72727273 | N3: Riel 3,3 | O3: 57 | P3: =+O3/3.2 -> 17.8125 | R3: Growatt | S3: 2000 | T3: 540 | U3: =+T3/S3 -> 0.27 | V3: Fajardo OFF | W3: 2200 | X3: 15032 | Y3: =+X3/W3 -> 6.8327273
A4: Interruptor Termomagnético 3P 32 A | B4: un | C4: 6.1 | D4: =+C4*0.85 -> 5.185 | E4: =+D4*1.22 -> 6.3257 | F4: MGI | J4: 540 | K4: 320 | L4: =+K4/J4 -> 0.59259259 | N4: Riel 3,2 | O4: 47 | P4: =+O4/3.2 -> 14.6875 | S4: 3000 | T4: 816 | U4: =+T4/S4 -> 0.272 | V4: Sandro Lopez | W4: =4*410 -> 1640 | X4: 3492 | Y4: =+X4/W4 -> 2.1292683 | Z4: 300 | AA4: 61 | AB4: =500*AA4/40 -> 762.5 | AC4: =+AB4/W4 -> 0.46493902
A5: Diferencial 40A 4P 300mA | B5: un | C5: 32.68 | D5: =+C5*0.85 -> 27.778 | E5: =+D5*1.22 -> 33.88916 | F5: MGI | J5: 410 | K5: 320 | L5: =+K5/J5 -> 0.7804878 | N5: Riel 2,2 | O5: 33 | P5: =+O5/2.2 -> 15 | V5: Stratta | W5: 2000 | X5: 4800 | Y5: =+X5/W5 -> 2.4 | Z5: 500 | AA5: 120 | AB5: =500*AA5/40 -> 1500 | AC5: =+AB5/W5 -> 0.75
A6: Diferencial 25A Monofasica 300mA | B6: un | C6: 19.09 | D6: =+C6*0.85 -> 16.2265 | E6: =+D6*1.22 -> 19.79633 | F6: MGI | N6: Union riel | O6: 5 | S6: Wifi | T6: 68 | V6: Silveira | W6: 3000 | X6: 6000 | Y6: =+X6/W6 -> 2 | Z6: 450 | AA6: 48 | AB6: =500*AA6/40 -> 600 | AC6: =+AB6/W6 -> 0.2
A7: Poteccion Sobretension 1P 275V Clamper | B7: un | C7: 44.3 | D7: =+C7*0.85 -> 37.655 | E7: =+D7*1.22 -> 45.9391 | F7: MGI
A8: Fusible 20A ceramico | B8: un | C8: 0.6 | D8: =+C8*0.85 -> 0.51 | E8: =+D8*1.22 -> 0.6222 | F8: MGI | N8: Sujetador final | O8: 5 | S8: Meter | T8: 95 | V8: Lebed | W8: 2700 | X8: 5400 | Y8: =+X8/W8 -> 2 | Z8: 421 | AA8: 83 | AB8: =500*AA8/40 -> 1037.5 | AC8: =+AB8/W8 -> 0.38425926
A9: Base portafusible RIEL DIN compatible c/fusibles | B9: un | C9: 4.16 | D9: =+C9*0.85 -> 3.536 | E9: =+D9*1.22 -> 4.31392 | F9: MGI | N9: Fujetador inter | O9: 5 | R9: Fronius | S9: 3000 | T9: 1500
A10: Caño galvanizado metalico 1'' de 3mts | B10: un | D10: =+C10*0.85 -> 0 | E10: =+D10*1.22 -> 0 | F10: MGI
A11: Codo 90º aluminio p/caño galv. 1'' exterior | B11: un | D11: =+C11*0.85 -> 0 | E11: =+D11*1.22 -> 0 | F11: MGI
A12: Cupla p/caño galv. 1'' exterior | B12: un | D12: =+C12*0.85 -> 0 | E12: =+D12*1.22 -> 0 | F12: MGI
A13: Conector p/caño galv. 1'' exterior | B13: un | C13: 0.44 | D13: =+C13*0.85 -> 0.374 | E13: =+D13*1.22 -> 0.45628 | F13: MGI | N13: Pata L | O13: 1 | S13: Meter pichi | T13: 55 | AA13: =+AA4/4/8 -> 1.90625 | AB13: =+AA13/W4*1000 -> 1.1623476
A14: Grampa p/caño galvanizado 1'' | B14: un | C14: 0.7 | D14: =+C14*0.85 -> 0.595 | E14: =+D14*1.22 -> 0.7259 | F14: MGI | N14: Triangulo | O14: 60 | AA14: =+AA5/4/8 -> 3.75 | AB14: =+AA14/W5*1000 -> 1.875
A15: Corrugado metalico 1'' | B15: mts | C15: 1.43 | D15: =+C15*0.85 -> 1.2155 | E15: =+D15*1.22 -> 1.48291 | F15: MGI
A16: Conector caño flexible Corrugado metalico 1'' | B16: un | C16: 2.49 | D16: =+C16*0.85 -> 2.1165 | E16: =+D16*1.22 -> 2.58213 | F16: MGI
A17: Caño galvanizado metalico 1 1/4" de 3mts | B17: un | D17: =+C17*0.85 -> 0 | E17: =+D17*1.22 -> 0 | F17: MGI
A18: Codo 90º aluminio p/caño galv. 1 1/4" exterior | B18: un | D18: =+C18*0.85 -> 0 | E18: =+D18*1.22 -> 0 | F18: MGI
A19: Cupla p/caño galv. 1 1/4" exterior | B19: un | D19: =+C19*0.85 -> 0 | E19: =+D19*1.22 -> 0 | F19: MGI
A20: Conector p/caño galv. 1 1/4" exterior | B20: un | D20: =+C20*0.85 -> 0 | E20: =+D20*1.22 -> 0 | F20: MGI
A21: Grampa p/caño galvanizado 1 1/4" | B21: un | D21: =+C21*0.85 -> 0 | E21: =+D21*1.22 -> 0 | F21: MGI
A22: Corrugado metalico 1 1/4" | B22: mts | C22: 1.69 | D22: =+C22*0.85 -> 1.4365 | E22: =+D22*1.22 -> 1.75253 | F22: MGI | N22: MC4 | O22: 5 | AA22: =+AA6/4/8 -> 1.5 | AB22: =+AA22/W6*1000 -> 0.5
A23: Conector caño flexible Corrugado metalico 1 1/4" | B23: un | C23: 3.87 | D23: =+C23*0.85 -> 3.2895 | E23: =+D23*1.22 -> 4.01319 | F23: MGI
A24: Cable multifilar Celeste 4mm2 | B24: mts | C24: 0.65 | D24: =+C24*0.85 -> 0.5525 | E24: =+D24*1.22 -> 0.67405 | F24: MGI | N24: Triangulo hormigon | O24: 30 | AA24: =+AA8/4/8 -> 2.59375 | AB24: =+AA24/W8*1000 -> 0.96064815
A25: Cable multifilar Rojo 4mm2 | B25: mts | C25: 0.65 | D25: =+C25*0.85 -> 0.5525 | E25: =+D25*1.22 -> 0.67405 | F25: MGI | N25: Loza hormigon | O25: 27
A26: Cable multifilar Marron 4mm2 | B26: mts | C26: 0.65 | D26: =+C26*0.85 -> 0.5525 | E26: =+D26*1.22 -> 0.67405 | F26: MGI | N26: Perfil galvanizado 6 mts | O26: 110
A27: Cable multifilar Celeste 6mm2 | B27: mts | C27: 1.07 | D27: =+C27*0.85 -> 0.9095 | E27: =+D27*1.22 -> 1.10959 | F27: MGI
A28: Cable multifilar Rojo 6mm2 | B28: mts | C28: 1.07 | D28: =+C28*0.85 -> 0.9095 | E28: =+D28*1.22 -> 1.10959 | F28: MGI
A29: Cable multifilar Marron 6mm2 | B29: mts | C29: 1.07 | D29: =+C29*0.85 -> 0.9095 | E29: =+D29*1.22 -> 1.10959 | F29: MGI
A30: Cable multifilar Celeste 10mm2 | B30: mts | C30: 1.84 | D30: =+C30*0.85 -> 1.564 | E30: =+D30*1.22 -> 1.90808 | F30: MGI
A31: Cable multifilar Rojo 10mm2 | B31: mts | C31: 1.84 | D31: =+C31*0.85 -> 1.564 | E31: =+D31*1.22 -> 1.90808 | F31: MGI
A32: Cable multifilar Marron 10mm2 | B32: mts | C32: 1.84 | D32: =+C32*0.85 -> 1.564 | E32: =+D32*1.22 -> 1.90808 | F32: MGI
A33: Cable multifilar Verde-amarillo 4mm | B33: mts | C33: 0.6 | D33: =+C33*0.85 -> 0.51 | E33: =+D33*1.22 -> 0.6222 | F33: MGI | O33: Minima | Q33: Minima 2 | S33: Stratta | U33: Hormigon
A34: Cable multifilar Verde-amarillo 6mm | B34: mts | C34: 1.07 | D34: =+C34*0.85 -> 0.9095 | E34: =+D34*1.22 -> 1.10959 | F34: MGI
A35: Cable multifilar Verde-amarillo 10mm | B35: mts | C35: 1.84 | D35: =+C35*0.85 -> 1.564 | E35: =+D35*1.22 -> 1.90808 | F35: MGI
A36: Cable superplastico 2x4mm | B36: mts | C36: 1.59 | D36: =+C36*0.85 -> 1.3515 | E36: =+D36*1.22 -> 1.64883 | F36: MGI | O36: Cantidad | P36: Precio | Q36: Cantidad | R36: Precio | S36: Cantidad | T36: Precio | U36: Cantidad | V36: Precio
A37: Cable superplastico 2x6mm | B37: mts | D37: =+C37*0.85 -> 0 | E37: =+D37*1.22 -> 0 | F37: MGI
A38: Cable superplastico 2x10mm | B38: mts | D38: =+C38*0.85 -> 0 | E38: =+D38*1.22 -> 0 | F38: MGI
A39: Bornera de paso 35mm2 riel din | B39: un | C39: 2.63 | D39: =+C39*0.85 -> 2.2355 | E39: =+D39*1.22 -> 2.72731 | F39: MGI | N39: Paneles | O39: 4 | Q39: 4 | S39: 4 | U39: 10
A40: Peine Unión Bornera de paso 35mm2 | B40: un | C40: 6.52 | D40: =+C40*0.85 -> 5.542 | E40: =+D40*1.22 -> 6.76124 | F40: MGI | N40: Rieles 3,3 | O40: 4 | P40: =+O40*O3 -> 228 | Q40: 6 | R40: =+Q40*$O$3 -> 342 | S40: 6 | T40: =+S40*$O$3 -> 342 | U40: 6 | V40: =+U40*$O$3 -> 342
...

Sheet Importación paneles
A2: Cajas | B2: 1 | C2: 2 | D2: 10 | E2: 14 | F2: 15 | G2: 20 | H2: 28 | I2: 30 | J2: 60 | K2: 100
A3: Metros cuadrados | B3: =+ROUNDUP(B2/$B$20,0) -> 1 | C3: =+ROUNDUP(C2/$B$20,0) -> 1 | D3: =+ROUNDUP(D2/$B$20,0) -> 1 | E3: =+ROUNDUP(E2/$B$20,0) -> 1 | F3: =+ROUNDUP(F2/$B$20,0) -> 2 | G3: =+ROUNDUP(G2/$B$20,0) -> 2 | H3: =+ROUNDUP(H2/$B$20,0) -> 2 | I3: =+ROUNDUP(I2/$B$20,0) -> 3 | ... K3: =+ROUNDUP(K2/$B$20,0) -> 8
A4: Potencia | B4: 600 | C4: 600 | D4: =+$B$4*D2 -> 6000 | E4: =+$B$4*E2 -> 8400 | F4: =+$B$4*F2 -> 9000 | G4: =+$B$4*G2 -> 12000 | H4: =+$B$4*H2 -> 16800 | I4: =+$B$4*I2 -> 18000 | J4: =+$B$4*J2 -> 36000 | K4: =+$B$4*K2 -> 60000
A5: Producto | B5: 157.14 | C5: =+$B$5*C2 -> 314.28 | D5: =+$B$5*D2 -> 1571.4 | E5: =+$B$5*E2 -> 2199.96 | F5: =+$B$5*F2 -> 2357.1 | G5: =+$B$5*G2 -> 3142.8 | H5: =+$B$5*H2 -> 4399.92 | I5: =+$B$5*I2 -> 4714.2 | J5: =+$B$5*J2 -> 9428.4 | K5: =+$B$5*K2 -> 15714
A6: Comision | B6: 27.71 | C6: 46.88 | D6: 200.25 | E6: 276.94 | F6: 304.65 | G6: 400.5 | H6: 553.87 | I6: 600.75 | J6: 1192.96 | K6: 1985.43
A7: Gastos origen | B7: 70 | C7: 70 | D7: 70 | E7: 70 | F7: 140 | G7: 140 | H7: 140 | I7: 210 | J7: 350 | K7: =+K3*$B$21 -> 560
A8: Gastos destino e impuestos | B8: 410.28 | C8: 504.57 | D8: 1258.84 | E8: 1635.98 | F8: 1998.26 | G8: 2469.68 | H8: 3223.95 | I8: 3680.52 | J8: 7045.04 | K8: =+$B$23*K3+K5*$B$24 -> 11956.4
A9: Fletes y seguro | B9: 395 | C9: 395 | D9: 395 | E9: 395 | F9: 730 | G9: 730 | H9: 730 | I9: 1065 | J9: 1735 | K9: =+LOOKUP(K3,D20:D29,E20:E29)*K3 -> 2600
A11: TOTAL | B11: =SUM(B5:B10) -> 1060.13 | C11: =SUM(C5:C10) -> 1330.73 | D11: =SUM(D5:D10) -> 3495.49 | E11: =SUM(E5:E10) -> 4577.88 | F11: =SUM(F5:F10) -> 5530.01 | G11: =SUM(G5:G10) -> 6882.98 | H11: =SUM(H5:H10) -> 9047.74 | I11: =SUM(I5:I10) -> 10270.47 | ... K11: =SUM(K5:K10) -> 32815.83
A14: $/W origen | B14: =+B5/B4 -> 0.2619 | C14: =+C5/C4 -> 0.5238 | D14: =+D5/D4 -> 0.2619 | E14: =+E5/E4 -> 0.2619 | F14: =+F5/F4 -> 0.2619 | G14: =+G5/G4 -> 0.2619 | H14: =+H5/H4 -> 0.2619 | I14: =+I5/I4 -> 0.2619 | J14: =+J5/J4 -> 0.2619
A15: $/W final | B15: =+B11/B4 -> 1.7668833 | C15: =+C11/C4 -> 2.2178833 | D15: =+D11/D4 -> 0.58258167 | E15: =+E11/E4 -> 0.54498571 | F15: =+F11/F4 -> 0.61444556 | G15: =+G11/G4 -> 0.57358167 | H15: =+H11/H4 -> 0.53855595 | I15: =+I11/I4 -> 0.57058167 | ... K15: =+K11/K4 -> 0.5469305
A19: Potencia/caja | B19: 600 | D19: Metros | E19: Flete/metro | G19: Calculadora
A20: Cajas por metro | B20: 14 | D20: 1 | E20: 395 | G20: Cajas | I20: =+E32 -> 10
A21: Gastos origen/metro | B21: 70 | D21: 2 | E21: 365 | G21: Paneles | I21: =+I20*2 -> 20
A22: Comision | B22: 0.1274 | D22: 3 | E22: 355 | G22: Potencia (kW) | I22: =+I20*B19/1000 -> 6
A23: Gastos destino/metro | B23: 316 | D23: 4 | E23: 350 | G23: Metros | I23: =+ROUNDUP(I20/$B$20,0) -> 1
A24: Impuesto | B24: 0.6 | D24: 5 | E24: 347 | G24: Producto (USD) | I24: =+I20*B26 -> 1571.4
A25: Flete/metro | B25: 395 | D25: 6 | E25: 345 | G25: Comision (USD) | I25: =+I24*B22 -> 200.19636
A26: Precio por caja | B26: 157.14 | D26: 7 | E26: 326.4 | G26: Gastos origen (USD) | I26: =+I23*B21 -> 70
D27: 8 | E27: 325 | G27: Gastos destino e impuestos (USD) | I27: =+B23*I23+I24*B24 -> 1258.84
D28: 9 | E28: 324 | G28: Fletes y seguro (USD) | I28: =+LOOKUP(I23,D20:D29,E20:E29)*I23 -> 395
D29: 10 | E29: 323
A30: Costo cada panel | B30: =+B19/2*I31 -> 174.77182 | G30: TOTAL (USD sin iva) | I30: =SUM(I24:I29) -> 3495.4364
D31: Necesidad paneles | E31: =+'Costeo China'!G3 -> 19 | G31: USD/W final (sin iva) | I31: =+I30/I22/1000 -> 0.58257273
D32: Cajas | E32: =+ROUNDUP(E31/2,0) -> 10
D33: Paneles sobrantes | E33: =+E32*2-E31 -> 1

Sheet Lista Materiales
A1: Item | B1: Unidades | C1: sin desc | D1: Precio unitario (USD) sin iva | E1: Precio unitario (USD) iva inc | F1: Cantidad | G1: Precio subtotal (USD) sin IVA | H1: Precio subtotal (USD) iva inc | I1: Nota
A2: MATERIALES ELECTRICOS
A3: Interruptor Termomagnético 25A | B3: un | C3: 3.6 | D3: =+C3*0.85 -> 3.06 | E3: =+D3*1.22 -> 3.7332 | G3: =+H3/1.22 -> 0 | H3: =+F3*E3 -> 0 | I3: MGI
A4: Interruptor Termomagnético 32A | B4: un | C4: 4.6 | D4: =+C4*0.85 -> 3.91 | E4: =+D4*1.22 -> 4.7702 | G4: =+H4/1.22 -> 0 | H4: =+F4*E4 -> 0 | I4: MGI
A5: Diferencial 40A 300mA | B5: un | C5: 18.03 | D5: =+C5*0.85 -> 15.3255 | E5: =+D5*1.22 -> 18.69711 | G5: =+H5/1.22 -> 0 | H5: =+F5*E5 -> 0 | I5: MGI
A6: Fusible 20A ceramico | B6: un | C6: 0.6 | D6: =+C6*0.85 -> 0.51 | E6: =+D6*1.22 -> 0.6222 | G6: =+H6/1.22 -> 0 | H6: =+F6*E6 -> 0 | I6: MGI
A7: Base portafusible RIEL DIN compatible c/fusibles | B7: un | C7: 4.16 | D7: =+C7*0.85 -> 3.536 | E7: =+D7*1.22 -> 4.31392 | G7: =+H7/1.22 -> 0 | H7: =+F7*E7 -> 0 | I7: MGI
A8: Conector p/caño galv. 1'' exterior | B8: un | C8: 0.44 | D8: =+C8*0.85 -> 0.374 | E8: =+D8*1.22 -> 0.45628 | G8: =+H8/1.22 -> 0 | H8: =+F8*E8 -> 0 | I8: MGI
A9: Grampa p/caño galvanizado 1'' | B9: un | C9: 0.7 | D9: =+C9*0.85 -> 0.595 | E9: =+D9*1.22 -> 0.7259 | G9: =+H9/1.22 -> 0 | H9: =+F9*E9 -> 0 | I9: MGI
A10: Caño galvanizado 1'' de 3mts | B10: un | C10: 3.76 | D10: =+C10*0.85 -> 3.196 | E10: =+D10*1.22 -> 3.89912 | G10: =+H10/1.22 -> 0 | H10: =+F10*E10 -> 0 | I10: MGI
A11: Codos galvanizados 1'' | B11: un | C11: 1.05 | D11: =+C11*0.85 -> 0.8925 | E11: =+D11*1.22 -> 1.08885 | G11: =+H11/1.22 -> 0 | H11: =+F11*E11 -> 0 | I11: MGI
A12: Cupla galvanizada 1'' | B12: un | C12: 0.33 | D12: =+C12*0.85 -> 0.2805 | E12: =+D12*1.22 -> 0.34221 | G12: =+H12/1.22 -> 0 | H12: =+F12*E12 -> 0 | I12: MGI
A13: Corrugado metalico 1'' | B13: mts | C13: 1.43 | D13: =+C13*0.85 -> 1.2155 | E13: =+D13*1.22 -> 1.48291 | G13: =+H13/1.22 -> 0 | H13: =+F13*E13 -> 0 | I13: MGI
A14: Conector corrugado metalico 1'' | C14: 1 | D14: =+C14*0.85 -> 0.85 | E14: =+D14*1.22 -> 1.037 | G14: =+H14/1.22 -> 0 | H14: =+F14*E14 -> 0 | I14: MGI
A15: Conector p/caño galv. 1 1/4'' exterior | B15: un | C15: 0.65 | D15: =+C15*0.85 -> 0.5525 | E15: =+D15*1.22 -> 0.67405 | G15: =+H15/1.22 -> 0 | H15: =+F15*E15 -> 0 | I15: MGI
A16: Caño galvanizado 1 1/4'' de 3mts | B16: un | C16: 5.7 | D16: =+C16*0.85 -> 4.845 | E16: =+D16*1.22 -> 5.9109 | G16: =+H16/1.22 -> 0 | H16: =+F16*E16 -> 0 | I16: MGI
A17: Codos galvanizados 1 1/4'' | B17: un | C17: 1.33 | D17: =+C17*0.85 -> 1.1305 | E17: =+D17*1.22 -> 1.37921 | G17: =+H17/1.22 -> 0 | H17: =+F17*E17 -> 0 | I17: MGI
A18: Cupla galvanizada p/corrugado metalico 1 1/4'' | B18: un | C18: 0.44 | D18: =+C18*0.85 -> 0.374 | E18: =+D18*1.22 -> 0.45628 | G18: =+H18/1.22 -> 0 | H18: =+F18*E18 -> 0 | I18: MGI
A19: Grampa p/caño galvanizado 1 1/4'' | B19: un | C19: 0.69 | D19: =+C19*0.85 -> 0.5865 | E19: =+D19*1.22 -> 0.71553 | G19: =+H19/1.22 -> 0 | H19: =+F19*E19 -> 0 | I19: MGI
A20: Corrugado metalico 1 1/4'' | B20: mts | C20: 1.69 | D20: =+C20*0.85 -> 1.4365 | E20: =+D20*1.22 -> 1.75253 | G20: =+H20/1.22 -> 0 | H20: =+F20*E20 -> 0 | I20: MGI
A21: Conector corrugado metalico 1 1/4'' | C21: 1.5 | D21: =+C21*0.85 -> 1.275 | E21: =+D21*1.22 -> 1.5555 | G21: =+H21/1.22 -> 0 | H21: =+F21*E21 -> 0 | I21: MGI
A22: Cable superplastico 2x4mm | B22: mts | C22: 1.59 | D22: =+C22*0.85 -> 1.3515 | E22: =+D22*1.22 -> 1.64883 | G22: =+H22/1.22 -> 0 | H22: =+F22*E22 -> 0 | I22: MGI
A23: Cable superplastico 2x6mm | B23: mts | C23: 2.5 | D23: =+C23*0.85 -> 2.125 | E23: =+D23*1.22 -> 2.5925 | G23: =+H23/1.22 -> 0 | H23: =+F23*E23 -> 0 | I23: MGI
A24: Cable superplastico 2x10mm | C24: 3.98 | D24: =+C24*0.85 -> 3.383 | E24: =+D24*1.22 -> 4.12726 | G24: =+H24/1.22 -> 0 | H24: =+F24*E24 -> 0 | I24: MGI
A25: Cable superplastico 2x16mm | C25: 6.76 | D25: =+C25*0.85 -> 5.746 | E25: =+D25*1.22 -> 7.01012 | G25: =+H25/1.22 -> 0 | H25: =+F25*E25 -> 0 | I25: MGI
A26: Cable multifilar Marron/blanco 6mm2 | C26: 1 | D26: =+C26*0.85 -> 0.85 | E26: =+D26*1.22 -> 1.037 | G26: =+H26/1.22 -> 0 | H26: =+F26*E26 -> 0 | I26: MGI
A27: Cable multifilar Celeste 6mm2 | B27: mts | C27: 0.97 | D27: =+C27*0.85 -> 0.8245 | E27: =+D27*1.22 -> 1.00589 | G27: =+H27/1.22 -> 0 | H27: =+F27*E27 -> 0 | I27: MGI
A28: Cable multifilar Rojo 6mm2 | B28: mts | C28: 0.97 | D28: =+C28*0.85 -> 0.8245 | E28: =+D28*1.22 -> 1.00589 | G28: =+H28/1.22 -> 0 | H28: =+F28*E28 -> 0 | I28: MGI
A29: Cable multifilar (TIERRA) Verde-amarillo 4mm | B29: mts | C29: 0.65 | D29: =+C29*0.85 -> 0.5525 | E29: =+D29*1.22 -> 0.67405 | G29: =+H29/1.22 -> 0 | H29: =+F29*E29 -> 0 | I29: MGI
A30: Cable multifilar (TIERRA) Verde-amarillo 6mm | C30: 1 | D30: =+C30*0.85 -> 0.85 | E30: =+D30*1.22 -> 1.037 | G30: =+H30/1.22 -> 0 | H30: =+F30*E30 -> 0 | I30: MGI
A31: Cable multifilar (TIERRA) Verde-amarillo 10mm | C31: 1.74 | D31: =+C31*0.85 -> 1.479 | E31: =+D31*1.22 -> 1.80438 | G31: =+H31/1.22 -> 0 | H31: =+F31*E31 -> 0 | I31: MGI
A32: Cable multifilar Marron/blanco 10mm2 | C32: 1.74 | D32: =+C32*0.85 -> 1.479 | E32: =+D32*1.22 -> 1.80438 | G32: =+H32/1.22 -> 0 | H32: =+F32*E32 -> 0 | I32: MGI
A33: Cable multifilar Celeste 10mm2 | B33: mts | C33: 1.74 | D33: =+C33*0.85 -> 1.479 | E33: =+D33*1.22 -> 1.80438 | G33: =+H33/1.22 -> 0 | H33: =+F33*E33 -> 0 | I33: MGI
A34: Cable multifilar Rojo 10mm2 | B34: mts | C34: 1.74 | D34: =+C34*0.85 -> 1.479 | E34: =+D34*1.22 -> 1.80438 | G34: =+H34/1.22 -> 0 | H34: =+F34*E34 -> 0 | I34: MGI
A35: Cable multifilar Marron/blanco 16mm2 | C35: 2.73 | D35: =+C35*0.85 -> 2.3205 | E35: =+D35*1.22 -> 2.83101 | G35: =+H35/1.22 -> 0 | H35: =+F35*E35 -> 0 | I35: MGI
A36: Cable multifilar Celeste 16mm2 | C36: 2.73 | D36: =+C36*0.85 -> 2.3205 | E36: =+D36*1.22 -> 2.83101 | G36: =+H36/1.22 -> 0 | H36: =+F36*E36 -> 0 | I36: MGI
A37: Cable multifilar Rojo 16mm2 | C37: 2.73 | D37: =+C37*0.85 -> 2.3205 | E37: =+D37*1.22 -> 2.83101 | G37: =+H37/1.22 -> 0 | H37: =+F37*E37 -> 0 | I37: MGI
A38: Bornera de paso 35mm2 riel din | B38: un | C38: 2.13 | D38: =+C38*0.85 -> 1.8105 | E38: =+D38*1.22 -> 2.20881 | G38: =+H38/1.22 -> 0 | H38: =+F38*E38 -> 0 | I38: MGI
A39: Peine Unión Bornera de paso 35mm2 | B39: un | C39: 5.75 | D39: =+C39*0.85 -> 4.8875 | E39: =+D39*1.22 -> 5.96275 | G39: =+H39/1.22 -> 0 | H39: =+F39*E39 -> 0 | I39: MGI
A40: Jabalina PAT 2000mm x 3/4'' | B40: un | C40: 22.34 | D40: =+C40*0.85 -> 18.989 | E40: =+D40*1.22 -> 23.16658 | G40: =+H40/1.22 -> 0 | H40: =+F40*E40 -> 0 | I40: MGI
...

Sheet Financiacion BBVA
A1: Tasa | B1: 0 | D1: 0 | F1: 0.05
A2: Precio | B2: =+CALCULADORA!J13 -> 12846.142
A3: Cuotas | B3: 24 | D3: 36 | F3: 60
A4: Valor UI | B4: 6.33
A5: Valor USD | B5: 40
A6: Gastos admin | B6: 0.025 | D6: 0.045 | F6: 0.01522
A7: Capital liquido | B7: =+$B$2*$B$5/$B$4 -> 81176.255 | C7: =+B7*$B$4 -> 513845.69 | D7: =+$B$2*$B$5/$B$4 -> 81176.255 | E7: =+D7*$B$4 -> 513845.69 | F7: =+$B$2*$B$5/$B$4 -> 81176.255 | G7: =+F7*$B$4 -> 513845.69
A8: Capital total | B8: =+B7+B9 -> 83205.661 | C8: =+B8*$B$4 -> 526691.83 | D8: =+D7+D9 -> 84829.186 | E8: =+D8*$B$4 -> 536968.75 | F8: =+F7+F9 -> 82411.757 | G8: =+F8*$B$4 -> 521666.42
A9: Gastos admin 2 | B9: =+B7*B6 -> 2029.4064 | C9: =+B9*B4 -> 12846.142 | D9: =+D7*D6 -> 3652.9315 | E9: =+D9*D4 -> 0 | F9: =+F7*F6 -> 1235.5026 | G9: =+F9*F4 -> 0
A10: Cuota sin | B10: =-PMT(B1/12,B3,B8) -> 3466.9025 | C10: =+B10*$B$4 -> 21945.493 | D10: =-PMT(D1/12,D3,D8) -> 2356.3663 | E10: =+D10*$B$4 -> 14915.799 | F10: =-PMT(F1/12,F3,F8) -> 1555.2115 | G10: =+F10*$B$4 -> 9844.489
A11: Cuota final | B11: =+B10*1.023 -> 3546.6413 | C11: =+B11*$B$4 -> 22450.239 | D11: =+D10*1.036 -> 2441.1955 | E11: =+D11*$B$4 -> 15452.767 | F11: =+F10*1.071 -> 1665.6315 | G11: =+F11*$B$4 -> 10543.448

Sheet Rentabilidad
B1: Entrada | C1: Salida | E1: Instalacion
A2: Adelanto 50% | B2: 3721
A3: Equipamiento | C3: =+C21 -> 129.32
A4: Otros (ferreteria, nafta, flete, etc) | C4: =+F32/J20 -> 187.80488 | E4: Leo Instalación | F4: 10000
A5: Instalación y relevamiento | C5: =+F10/J20 -> 731.70732 | E5: Mauri Instalación | F5: 10000
A6: Impuestos | C6: 550 | E6: Nico -Jorge Instalación | F6: 10000
A7: Saldo 50% | B7: =7442-B2 -> 3721
B9: =SUM(B2:B8) -> 7442 | C9: =SUM(C2:C8) -> 1598.8322
F10: =SUM(F2:F8) -> 30000
A11: Ganancia | B11: =+B9-C9 -> 5843.1678
A12: Margen | B12: =+B11/B9 -> 0.78516095
A20: Item | I20: Dólar | J20: 41
A21: Materiales Electricos | B21: =+'Lista Materiales'!H46 -> 0 | C21: =SUM(B21:B24) -> 129.32 | E21: Otros
A22: Estructuras | B22: =+'Lista Materiales'!H59 -> 0 | E22: Comida viaje | F22: 700
A23: Paneles | B23: =+'Lista Materiales'!H63 -> 58.56 | E23: Flete | F23: 5000
A24: Inversor | B24: =+'Lista Materiales'!H62+'Lista Materiales'!H64+'Lista Materiales'!H65 -> 70.76 | E24: Alojamiento
A25: Otros | B25: =+F32/J20 -> 187.80488 | E25: Ferreteria | F25: 0
A26: Instaladores | B26: =+F10/J20 -> 731.70732 | E26: Peajes
E27: Nafta | F27: 2000
B28: =SUM(B21:B27) -> 1048.8322 | E28: Agua
E32: Total | F32: =SUM(F22:F31) -> 7700
